<?xml version="1.0" ?>
<sdf version="1.7">
  <model name="cart_triple_pendulum">

    <link name="cart">
      <pose>0 0 0 0 0 0</pose>
      <inertial>
        <mass>1</mass>
      </inertial>
      <visual name="cart_body">
        <geometry>
          <box>
            <size>0.5 0.3 0.3</size>
          </box>
        </geometry>
        <material>
          <diffuse>0.5 0.5 0.5 1</diffuse>
        </material>
      </visual>
      <visual name="cart_wheel1">
        <pose>-0.15 0 -0.2 1.57 0 0</pose>
        <geometry>
          <cylinder>
            <radius>0.05</radius>
            <length>0.3</length>
          </cylinder>
        </geometry>
        <material>
          <diffuse>0 0 0 1</diffuse>
        </material>
      </visual>
      <visual name="cart_wheel2">
        <pose>0.15 0 -0.2 1.57 0 0</pose>
        <geometry>
          <cylinder>
            <radius>0.05</radius>
            <length>0.3</length>
          </cylinder>
        </geometry>
        <material>
          <diffuse>0 0 0 1</diffuse>
        </material>
      </visual>
    </link>

    <link name="pendulum1">
      <pose>0 -0.17 0 0 0 0</pose>
      <inertial>
        <pose>0 0 -0.5 0 0 0</pose>
        <mass>1</mass>
        <inertia>
          <ixx>0.08333333333</ixx>
          <iyy>0.08333333333</iyy>
          <izz>1e-5</izz>
        </inertia>
      </inertial>
      <visual name="pendulum1_rod">
        <pose>0 0 -0.5 0 0 0</pose>
        <geometry>
          <cylinder>
            <radius>0.02</radius>
            <length>1</length>
          </cylinder>
        </geometry>
        <material>
          <diffuse>1 0 0 1</diffuse>
        </material>
      </visual>
    </link>

    <link name="pendulum2">
      <pose>0 -0.21 -1 0 0 0</pose>
      <inertial>
        <pose>0 0 -0.5 0 0 0</pose>
        <mass>1</mass>
        <inertia>
          <ixx>0.08333333333</ixx>
          <iyy>0.08333333333</iyy>
          <izz>1e-5</izz>
        </inertia>
      </inertial>
      <visual name="pendulum2_rod">
        <pose>0 0 -0.5 0 0 0</pose>
        <geometry>
          <cylinder>
            <radius>0.02</radius>
            <length>1</length>
          </cylinder>
        </geometry>
        <material>
          <diffuse>0 1 0 1</diffuse>
        </material>
      </visual>
    </link>

    <link name="pendulum3">
      <pose>0 -0.25 -2 0 0 0</pose>
      <inertial>
        <pose>0 0 -0.5 0 0 0</pose>
        <mass>1</mass>
        <inertia>
          <ixx>0.08333333333</ixx>
          <iyy>0.08333333333</iyy>
          <izz>1e-5</izz>
        </inertia>
      </inertial>
      <visual name="pendulum3_rod">
        <pose>0 0 -0.5 0 0 0</pose>
        <geometry>
          <cylinder>
            <radius>0.02</radius>
            <length>1</length>
          </cylinder>
        </geometry>
        <material>
          <diffuse>0 0 1 1</diffuse>
        </material>
      </visual>
    </link>

    <joint name="linear" type="prismatic">
      <parent>world</parent>
      <child>cart</child>
      <axis>
        <xyz>1 0 0</xyz>
      </axis>
    </joint>

    <joint name="joint1" type="continuous">
      <parent>cart</parent>
      <child>pendulum1</child>
      <axis>
        <xyz>0 -1 0</xyz>
        <limit>
          <effort>0</effort> <!-- Unactuated -->
        </limit>
      </axis>
    </joint>

    <joint name="joint2" type="continuous">
      <parent>pendulum1</parent>
      <child>pendulum2</child>
      <axis>
        <xyz>0 -1 0</xyz>
        <limit>
          <effort>0</effort> <!-- Unactuated -->
        </limit>
      </axis>
    </joint>

    <joint name="joint3" type="continuous">
      <parent>pendulum2</parent>
      <child>pendulum3</child>
      <axis>
        <xyz>0 -1 0</xyz>
        <limit>
          <effort>0</effort> <!-- Unactuated -->
        </limit>
      </axis>
    </joint>

  </model>
</sdf>